Workbook

Sheet Provided Inputs
A1: Cost & Revenue
A2: Fixed Cost | B2: 500
A3: Variable Cost | B3: 5
A4: Revenue per Pizza | B4: 9
A6: Demand & Probability
A7: Demand | B7: Probability
A8: 300 | B8: 0.1
A9: 400 | B9: 0.2
A10: 500 | B10: 0.25
A11: 600 | B11: 0.25
A12: 700 | B12: 0.15
A13: 800 | B13: 0.05

Sheet Pepp EMV Model
A1: EMV If 300 Pizzas Are Produced
A2: Pizzas Produced | B2: Pepperoni-and-Cheese Demand | C2: Pizzas Sold | D2: Gross Revenue | E2: Fixed Cost | F2: Variable Cost | G2: Gross Profit | H2: Probability | I2: Expected Profit Adjusted For Probability
A3: 300 | B3: 300 | C3: =IF(B3<=A3,B3,A3) -> 300 | D3: =C3*'Provided Inputs'!B$4 -> 2700 | E3: ='Provided Inputs'!B$2 -> 500 | F3: =A3*'Provided Inputs'!B$3 -> 1500 | G3: =D3-SUM(E3:F3) -> 700 | H3: 0.1 | I3: =G3*H3 -> 70
A4: 300 | B4: 400 | C4: =IF(B4<=A4,B4,A4) -> 300 | D4: =C4*'Provided Inputs'!B$4 -> 2700 | E4: ='Provided Inputs'!B$2 -> 500 | F4: =A4*'Provided Inputs'!B$3 -> 1500 | G4: =D4-SUM(E4:F4) -> 700 | H4: 0.2 | I4: =G4*H4 -> 140
A5: 300 | B5: 500 | C5: =IF(B5<=A5,B5,A5) -> 300 | D5: =C5*'Provided Inputs'!B$4 -> 2700 | E5: ='Provided Inputs'!B$2 -> 500 | F5: =A5*'Provided Inputs'!B$3 -> 1500 | G5: =D5-SUM(E5:F5) -> 700 | H5: 0.25 | I5: =G5*H5 -> 175
A6: 300 | B6: 600 | C6: =IF(B6<=A6,B6,A6) -> 300 | D6: =C6*'Provided Inputs'!B$4 -> 2700 | E6: ='Provided Inputs'!B$2 -> 500 | F6: =A6*'Provided Inputs'!B$3 -> 1500 | G6: =D6-SUM(E6:F6) -> 700 | H6: 0.25 | I6: =G6*H6 -> 175
A7: 300 | B7: 700 | C7: =IF(B7<=A7,B7,A7) -> 300 | D7: =C7*'Provided Inputs'!B$4 -> 2700 | E7: ='Provided Inputs'!B$2 -> 500 | F7: =A7*'Provided Inputs'!B$3 -> 1500 | G7: =D7-SUM(E7:F7) -> 700 | H7: 0.15 | I7: =G7*H7 -> 105
A8: 300 | B8: 800 | C8: =IF(B8<=A8,B8,A8) -> 300 | D8: =C8*'Provided Inputs'!B$4 -> 2700 | E8: ='Provided Inputs'!B$2 -> 500 | F8: =A8*'Provided Inputs'!B$3 -> 1500 | G8: =D8-SUM(E8:F8) -> 700 | H8: 0.05 | I8: =G8*H8 -> 35 | J8: Total EMV | K8: =SUM(I3:I8) -> 700
A10: EMV If 400 Pizzas Are Produced
A11: Pizzas Produced | B11: Pepperoni-and-Cheese Demand | C11: Pizzas Sold | D11: Gross Revenue | E11: Fixed Cost | F11: Variable Cost | G11: Gross Profit | H11: Probability | I11: Expected Profit Adjusted For Probability
A12: 400 | B12: 300 | C12: =IF(B12<=A12,B12,A12) -> 300 | D12: =C12*'Provided Inputs'!B$4 -> 2700 | E12: ='Provided Inputs'!B$2 -> 500 | F12: =A12*'Provided Inputs'!B$3 -> 2000 | G12: =D12-SUM(E12:F12) -> 200 | H12: 0.1 | I12: =G12*H12 -> 20
A13: 400 | B13: 400 | C13: =IF(B13<=A13,B13,A13) -> 400 | D13: =C13*'Provided Inputs'!B$4 -> 3600 | E13: ='Provided Inputs'!B$2 -> 500 | F13: =A13*'Provided Inputs'!B$3 -> 2000 | G13: =D13-SUM(E13:F13) -> 1100 | H13: 0.2 | I13: =G13*H13 -> 220
A14: 400 | B14: 500 | C14: =IF(B14<=A14,B14,A14) -> 400 | D14: =C14*'Provided Inputs'!B$4 -> 3600 | E14: ='Provided Inputs'!B$2 -> 500 | F14: =A14*'Provided Inputs'!B$3 -> 2000 | G14: =D14-SUM(E14:F14) -> 1100 | H14: 0.25 | I14: =G14*H14 -> 275
A15: 400 | B15: 600 | C15: =IF(B15<=A15,B15,A15) -> 400 | D15: =C15*'Provided Inputs'!B$4 -> 3600 | E15: ='Provided Inputs'!B$2 -> 500 | F15: =A15*'Provided Inputs'!B$3 -> 2000 | G15: =D15-SUM(E15:F15) -> 1100 | H15: 0.25 | I15: =G15*H15 -> 275
A16: 400 | B16: 700 | C16: =IF(B16<=A16,B16,A16) -> 400 | D16: =C16*'Provided Inputs'!B$4 -> 3600 | E16: ='Provided Inputs'!B$2 -> 500 | F16: =A16*'Provided Inputs'!B$3 -> 2000 | G16: =D16-SUM(E16:F16) -> 1100 | H16: 0.15 | I16: =G16*H16 -> 165
A17: 400 | B17: 800 | C17: =IF(B17<=A17,B17,A17) -> 400 | D17: =C17*'Provided Inputs'!B$4 -> 3600 | E17: ='Provided Inputs'!B$2 -> 500 | F17: =A17*'Provided Inputs'!B$3 -> 2000 | G17: =D17-SUM(E17:F17) -> 1100 | H17: 0.05 | I17: =G17*H17 -> 55 | J17: Total EMV | K17: =SUM(I12:I17) -> 1010
A19: EMV If 500 Pizzas Are Produced
A20: Pizzas Produced | B20: Pepperoni-and-Cheese Demand | C20: Pizzas Sold | D20: Gross Revenue | E20: Fixed Cost | F20: Variable Cost | G20: Gross Profit | H20: Probability | I20: Expected Profit Adjusted For Probability
A21: 500 | B21: 300 | C21: =IF(B21<=A21,B21,A21) -> 300 | D21: =C21*'Provided Inputs'!B$4 -> 2700 | E21: ='Provided Inputs'!B$2 -> 500 | F21: =A21*'Provided Inputs'!B$3 -> 2500 | G21: =D21-SUM(E21:F21) -> -300 | H21: 0.1 | I21: =G21*H21 -> -30
A22: 500 | B22: 400 | C22: =IF(B22<=A22,B22,A22) -> 400 | D22: =C22*'Provided Inputs'!B$4 -> 3600 | E22: ='Provided Inputs'!B$2 -> 500 | F22: =A22*'Provided Inputs'!B$3 -> 2500 | G22: =D22-SUM(E22:F22) -> 600 | H22: 0.2 | I22: =G22*H22 -> 120
A23: 500 | B23: 500 | C23: =IF(B23<=A23,B23,A23) -> 500 | D23: =C23*'Provided Inputs'!B$4 -> 4500 | E23: ='Provided Inputs'!B$2 -> 500 | F23: =A23*'Provided Inputs'!B$3 -> 2500 | G23: =D23-SUM(E23:F23) -> 1500 | H23: 0.25 | I23: =G23*H23 -> 375
A24: 500 | B24: 600 | C24: =IF(B24<=A24,B24,A24) -> 500 | D24: =C24*'Provided Inputs'!B$4 -> 4500 | E24: ='Provided Inputs'!B$2 -> 500 | F24: =A24*'Provided Inputs'!B$3 -> 2500 | G24: =D24-SUM(E24:F24) -> 1500 | H24: 0.25 | I24: =G24*H24 -> 375
A25: 500 | B25: 700 | C25: =IF(B25<=A25,B25,A25) -> 500 | D25: =C25*'Provided Inputs'!B$4 -> 4500 | E25: ='Provided Inputs'!B$2 -> 500 | F25: =A25*'Provided Inputs'!B$3 -> 2500 | G25: =D25-SUM(E25:F25) -> 1500 | H25: 0.15 | I25: =G25*H25 -> 225
A26: 500 | B26: 800 | C26: =IF(B26<=A26,B26,A26) -> 500 | D26: =C26*'Provided Inputs'!B$4 -> 4500 | E26: ='Provided Inputs'!B$2 -> 500 | F26: =A26*'Provided Inputs'!B$3 -> 2500 | G26: =D26-SUM(E26:F26) -> 1500 | H26: 0.05 | I26: =G26*H26 -> 75 | J26: Total EMV | K26: =SUM(I21:I26) -> 1140
A28: EMV If 600 Pizzas Are Produced
A29: Pizzas Produced | B29: Pepperoni-and-Cheese Demand | C29: Pizzas Sold | D29: Gross Revenue | E29: Fixed Cost | F29: Variable Cost | G29: Gross Profit | H29: Probability | I29: Expected Profit Adjusted For Probability
A30: 600 | B30: 300 | C30: =IF(B30<=A30,B30,A30) -> 300 | D30: =C30*'Provided Inputs'!B$4 -> 2700 | E30: ='Provided Inputs'!B$2 -> 500 | F30: =A30*'Provided Inputs'!B$3 -> 3000 | G30: =D30-SUM(E30:F30) -> -800 | H30: 0.1 | I30: =G30*H30 -> -80
A31: 600 | B31: 400 | C31: =IF(B31<=A31,B31,A31) -> 400 | D31: =C31*'Provided Inputs'!B$4 -> 3600 | E31: ='Provided Inputs'!B$2 -> 500 | F31: =A31*'Provided Inputs'!B$3 -> 3000 | G31: =D31-SUM(E31:F31) -> 100 | H31: 0.2 | I31: =G31*H31 -> 20
A32: 600 | B32: 500 | C32: =IF(B32<=A32,B32,A32) -> 500 | D32: =C32*'Provided Inputs'!B$4 -> 4500 | E32: ='Provided Inputs'!B$2 -> 500 | F32: =A32*'Provided Inputs'!B$3 -> 3000 | G32: =D32-SUM(E32:F32) -> 1000 | H32: 0.25 | I32: =G32*H32 -> 250
A33: 600 | B33: 600 | C33: =IF(B33<=A33,B33,A33) -> 600 | D33: =C33*'Provided Inputs'!B$4 -> 5400 | E33: ='Provided Inputs'!B$2 -> 500 | F33: =A33*'Provided Inputs'!B$3 -> 3000 | G33: =D33-SUM(E33:F33) -> 1900 | H33: 0.25 | I33: =G33*H33 -> 475
A34: 600 | B34: 700 | C34: =IF(B34<=A34,B34,A34) -> 600 | D34: =C34*'Provided Inputs'!B$4 -> 5400 | E34: ='Provided Inputs'!B$2 -> 500 | F34: =A34*'Provided Inputs'!B$3 -> 3000 | G34: =D34-SUM(E34:F34) -> 1900 | H34: 0.15 | I34: =G34*H34 -> 285
A35: 600 | B35: 800 | C35: =IF(B35<=A35,B35,A35) -> 600 | D35: =C35*'Provided Inputs'!B$4 -> 5400 | E35: ='Provided Inputs'!B$2 -> 500 | F35: =A35*'Provided Inputs'!B$3 -> 3000 | G35: =D35-SUM(E35:F35) -> 1900 | H35: 0.05 | I35: =G35*H35 -> 95 | J35: Total EMV | K35: =SUM(I30:I35) -> 1045
A37: EMV If 700 Pizzas Are Produced
A38: Pizzas Produced | B38: Pepperoni-and-Cheese Demand | C38: Pizzas Sold | D38: Gross Revenue | E38: Fixed Cost | F38: Variable Cost | G38: Gross Profit | H38: Probability | I38: Expected Profit Adjusted For Probability
A39: 700 | B39: 300 | C39: =IF(B39<=A39,B39,A39) -> 300 | D39: =C39*'Provided Inputs'!B$4 -> 2700 | E39: ='Provided Inputs'!B$2 -> 500 | F39: =A39*'Provided Inputs'!B$3 -> 3500 | G39: =D39-SUM(E39:F39) -> -1300 | H39: 0.1 | I39: =G39*H39 -> -130
A40: 700 | B40: 400 | C40: =IF(B40<=A40,B40,A40) -> 400 | D40: =C40*'Provided Inputs'!B$4 -> 3600 | E40: ='Provided Inputs'!B$2 -> 500 | F40: =A40*'Provided Inputs'!B$3 -> 3500 | G40: =D40-SUM(E40:F40) -> -400 | H40: 0.2 | I40: =G40*H40 -> -80
A41: 700 | B41: 500 | C41: =IF(B41<=A41,B41,A41) -> 500 | D41: =C41*'Provided Inputs'!B$4 -> 4500 | E41: ='Provided Inputs'!B$2 -> 500 | F41: =A41*'Provided Inputs'!B$3 -> 3500 | G41: =D41-SUM(E41:F41) -> 500 | H41: 0.25 | I41: =G41*H41 -> 125
A42: 700 | B42: 600 | C42: =IF(B42<=A42,B42,A42) -> 600 | D42: =C42*'Provided Inputs'!B$4 -> 5400 | E42: ='Provided Inputs'!B$2 -> 500 | F42: =A42*'Provided Inputs'!B$3 -> 3500 | G42: =D42-SUM(E42:F42) -> 1400 | H42: 0.25 | I42: =G42*H42 -> 350
A43: 700 | B43: 700 | C43: =IF(B43<=A43,B43,A43) -> 700 | D43: =C43*'Provided Inputs'!B$4 -> 6300 | E43: ='Provided Inputs'!B$2 -> 500 | F43: =A43*'Provided Inputs'!B$3 -> 3500 | G43: =D43-SUM(E43:F43) -> 2300 | H43: 0.15 | I43: =G43*H43 -> 345
A44: 700 | B44: 800 | C44: =IF(B44<=A44,B44,A44) -> 700 | D44: =C44*'Provided Inputs'!B$4 -> 6300 | E44: ='Provided Inputs'!B$2 -> 500 | F44: =A44*'Provided Inputs'!B$3 -> 3500 | G44: =D44-SUM(E44:F44) -> 2300 | H44: 0.05 | I44: =G44*H44 -> 115 | J44: Total EMV | K44: =SUM(I39:I44) -> 725
...

Sheet Summary
A1: Expected Monetary Value Of Pepperoni Pizza By Production Levels
A2: Demand | B2: Probability | C2: EMV Across Production Levels
A3: 300 | B3: 0.1 | C3: =SUM('Pepp EMV Model'!I3:I8) -> 700
A4: 400 | B4: 0.2 | C4: =SUM('Pepp EMV Model'!I12:I17) -> 1010
A5: 500 | B5: 0.25 | C5: =SUM('Pepp EMV Model'!I21:I26) -> 1140
A6: 600 | B6: 0.25 | C6: =SUM('Pepp EMV Model'!I30:I35) -> 1045
A7: 700 | B7: 0.15 | C7: =SUM('Pepp EMV Model'!I39:I44) -> 725
A8: 800 | B8: 0.05 | C8: =SUM('Pepp EMV Model'!I48:I53) -> 270
